Workbook

Sheet Citywide Trends
A1: Years | B1: Total Auto Thefts
A2: 2014 | B2: =SUM('Cleaned Dataset'!B2:B159) -> 3573
A3: 2015 | B3: =SUM('Cleaned Dataset'!C2:C159) -> 3261
A4: 2016 | B4: =SUM('Cleaned Dataset'!D2:D159) -> 3311
A5: 2017 | B5: =SUM('Cleaned Dataset'!E2:E159) -> 3565
A6: 2018 | B6: =SUM('Cleaned Dataset'!F2:F159) -> 4747
A7: 2019 | B7: =SUM('Cleaned Dataset'!G2:G159) -> 5280
A8: 2020 | B8: =SUM('Cleaned Dataset'!H2:H159) -> 5740
A9: 2021 | B9: =SUM('Cleaned Dataset'!B9:B165) -> 2908
A10: 2022 | B10: =SUM('Cleaned Dataset'!J2:J159) -> 9746
A11: 2023 | B11: =SUM('Cleaned Dataset'!K2:K159) -> 12190
A12: 2024 | B12: =SUM('Cleaned Dataset'!L2:L159) -> 9256
A19: Top 10 Neighborhoods by Total Auto Thefts
A20: Neighborhood | B20: 2014 | C20: 2015 | D20: 2016 | E20: 2017 | F20: 2018 | G20: 2019 | H20: 2020 | I20: 2021 | J20: 2022 | K20: 2023 | L20: 2024 | M20: Total Auto Thefts
A21: West Humber-Clairville | B21: 309 | C21: 265 | D21: 322 | E21: 325 | F21: 503 | G21: 486 | H21: 405 | I21: 498 | J21: 781 | K21: 837 | L21: 641 | M21: =SUM(B21:L21) -> 5372
A22: York University Heights | B22: 109 | C22: 101 | D22: 109 | E22: 93 | F22: 90 | G22: 148 | H22: 187 | I22: 174 | J22: 235 | K22: 264 | L22: 225 | M22: =SUM(B22:L22) -> 1735
A23: Etobicoke City Centre | B23: 64 | C23: 76 | D23: 103 | E23: 71 | F23: 122 | G23: 118 | H23: 102 | I23: 118 | J23: 189 | K23: 294 | L23: 261 | M23: =SUM(B23:L23) -> 1518
A24: Humber Summit | B24: 68 | C24: 41 | D24: 63 | E24: 83 | F24: 111 | G24: 136 | H24: 111 | I24: 139 | J24: 176 | K24: 132 | L24: 114 | M24: =SUM(B24:L24) -> 1174
A25: Wexford/Maryvale | B25: 60 | C25: 54 | D25: 44 | E25: 68 | F25: 87 | G25: 99 | H25: 89 | I25: 92 | J25: 130 | K25: 208 | L25: 182 | M25: =SUM(B25:L25) -> 1113
A26: Milliken | B26: 38 | C26: 43 | D26: 35 | E26: 60 | F26: 89 | G26: 85 | H26: 69 | I26: 80 | J26: 107 | K26: 305 | L26: 180 | M26: =SUM(B26:L26) -> 1091
A27: Yorkdale-Glen Park | B27: 67 | C27: 53 | D27: 41 | E27: 52 | F27: 63 | G27: 62 | H27: 88 | I27: 96 | J27: 196 | K27: 202 | L27: 112 | M27: =SUM(B27:L27) -> 1032
A28: Oakdale-Beverley Heights | B28: 66 | C28: 70 | D28: 51 | E28: 53 | F28: 75 | G28: 92 | H28: 103 | I28: 115 | J28: 106 | K28: 164 | L28: 110 | M28: =SUM(B28:L28) -> 1005
A29: Glenfield-Jane Heights | B29: 44 | C29: 50 | D29: 64 | E29: 50 | F29: 68 | G29: 83 | H29: 120 | I29: 106 | J29: 155 | K29: 120 | L29: 103 | M29: =SUM(B29:L29) -> 963
A30: Bedford Park-Nortown | B30: 40 | C30: 40 | D30: 30 | E30: 47 | F30: 49 | G30: 63 | H30: 81 | I30: 105 | J30: 172 | K30: 228 | L30: 101 | M30: =SUM(B30:L30) -> 956
A54: Top 10 Neighborhoods with Fastest Growth in Auto Thefts (2014–2024)
A55: Neighborhood | B55: 2014 | C55: 2015 | D55: 2016 | E55: 2017 | F55: 2018 | G55: 2019 | H55: 2020 | I55: 2021 | J55: 2022 | K55: 2023 | L55: 2024 | M55: PCT_CHANGE_2014_2024
A56: East L'Amoreaux | B56: 7 | C56: 8 | D56: 13 | E56: 11 | F56: 13 | G56: 14 | H56: 14 | I56: 19 | J56: 46 | K56: 53 | L56: 75 | M56: =IF(B56=0, "", ((L56 - B56) / B56) * 100) -> 971.42857
A57: Yonge-St.Clair | B57: 2 | C57: 3 | D57: 7 | E57: 2 | F57: 6 | G57: 6 | H57: 9 | I57: 13 | J57: 32 | K57: 40 | L57: 20 | M57: =IF(B57=0, "", ((L57 - B57) / B57) * 100) -> 900
A58: Malvern West | B58: 7 | C58: 18 | D58: 18 | E58: 30 | F58: 26 | G58: 38 | H58: 24 | I58: 22 | J58: 55 | K58: 55 | L58: 64 | M58: =IF(B58=0, "", ((L58 - B58) / B58) * 100) -> 814.28571
A59: Guildwood | B59: 2 | C59: 0 | D59: 4 | E59: 5 | F59: 2 | G59: 3 | H59: 11 | I59: 13 | J59: 9 | K59: 23 | L59: 17 | M59: =IF(B59=0, "", ((L59 - B59) / B59) * 100) -> 750
A60: South Eglinton-Davisville | B60: 2 | C60: 4 | D60: 3 | E60: 8 | F60: 15 | G60: 8 | H60: 14 | I60: 15 | J60: 10 | K60: 20 | L60: 16 | M60: =IF(B60=0, "", ((L60 - B60) / B60) * 100) -> 700
A61: Agincourt North | B61: 17 | C61: 29 | D61: 18 | E61: 33 | F61: 42 | G61: 42 | H61: 63 | I61: 52 | J61: 49 | K61: 125 | L61: 128 | M61: =IF(B61=0, "", ((L61 - B61) / B61) * 100) -> 652.94118
A62: Broadview North | B62: 2 | C62: 4 | D62: 7 | E62: 6 | F62: 6 | G62: 3 | H62: 7 | I62: 11 | J62: 15 | K62: 17 | L62: 15 | M62: =IF(B62=0, "", ((L62 - B62) / B62) * 100) -> 650
A63: Elms-Old Rexdale | B63: 7 | C63: 19 | D63: 16 | E63: 12 | F63: 33 | G63: 28 | H63: 42 | I63: 51 | J63: 60 | K63: 39 | L63: 52 | M63: =IF(B63=0, "", ((L63 - B63) / B63) * 100) -> 642.85714
A64: Rosedale-Moore Park | B64: 10 | C64: 27 | D64: 12 | E64: 7 | F64: 31 | G64: 34 | H64: 52 | I64: 73 | J64: 111 | K64: 144 | L64: 74 | M64: =IF(B64=0, "", ((L64 - B64) / B64) * 100) -> 640
A65: The Beaches | B65: 8 | C65: 24 | D65: 7 | E65: 11 | F65: 31 | G65: 20 | H65: 23 | I65: 30 | J65: 54 | K65: 59 | L65: 59 | M65: =IF(B65=0, "", ((L65 - B65) / B65) * 100) -> 637.5
A90: Top 10 Neighborhoods by Auto Theft Rate per 1,000 People (2024)
A91: Neighborhood | B91: 2014 | C91: 2015 | D91: 2016 | E91: 2017 | F91: 2018 | G91: 2019 | H91: 2020 | I91: 2021 | J91: 2022 | K91: 2023 | L91: 2024 | M91: POPULATION_2024 | N91: AUTOTHEFT_RATE_2024
A92: West Humber-Clairville | B92: 309 | C92: 265 | D92: 322 | E92: 325 | F92: 503 | G92: 486 | H92: 405 | I92: 498 | J92: 781 | K92: 837 | L92: 641 | M92: 39266 | N92: =L92 / M92 * 100000 -> 1632.4556
A93: Etobicoke City Centre | B93: 64 | C93: 76 | D93: 103 | E93: 71 | F93: 122 | G93: 118 | H93: 102 | I93: 118 | J93: 189 | K93: 294 | L93: 261 | M93: 23394 | N93: =L93 / M93 * 100000 -> 1115.6707
...

Sheet Cleaned Dataset
A1: AREA_NAME | B1: AUTOTHEFT_2014 | C1: AUTOTHEFT_2015 | D1: AUTOTHEFT_2016 | E1: AUTOTHEFT_2017 | F1: AUTOTHEFT_2018 | G1: AUTOTHEFT_2019 | H1: AUTOTHEFT_2020 | I1: AUTOTHEFT_2021 | J1: AUTOTHEFT_2022 | K1: AUTOTHEFT_2023 | L1: AUTOTHEFT_2024 | M1: TOTAL_AUTOTHEFTS | N1: PCT_CHANGE_2014_2024 | O1: POPULATION_2024 | P1: AUTOTHEFT_RATE_2024
A2: West Humber-Clairville | B2: 309 | C2: 265 | D2: 322 | E2: 325 | F2: 503 | G2: 486 | H2: 405 | I2: 498 | J2: 781 | K2: 837 | L2: 641 | M2: 5372 | N2: =IF(B2=0, "", ((L2 - B2) / B2) * 100) -> 107.44337 | O2: 39266 | P2: =L2 / O2 * 100000 -> 1632.4556
A3: Etobicoke City Centre | B3: 64 | C3: 76 | D3: 103 | E3: 71 | F3: 122 | G3: 118 | H3: 102 | I3: 118 | J3: 189 | K3: 294 | L3: 261 | M3: 1518 | N3: =IF(B3=0, "", ((L3 - B3) / B3) * 100) -> 307.8125 | O3: 23394 | P3: =L3 / O3 * 100000 -> 1115.6707
A4: Morningside Heights | B4: 31 | C4: 23 | D4: 16 | E4: 24 | F4: 46 | G4: 54 | H4: 43 | I4: 76 | J4: 132 | K4: 157 | L4: 129 | M4: 731 | N4: =IF(B4=0, "", ((L4 - B4) / B4) * 100) -> 316.12903 | O4: 12769 | P4: =L4 / O4 * 100000 -> 1010.2592
A5: Humber Summit | B5: 68 | C5: 41 | D5: 63 | E5: 83 | F5: 111 | G5: 136 | H5: 111 | I5: 139 | J5: 176 | K5: 132 | L5: 114 | M5: 1174 | N5: =IF(B5=0, "", ((L5 - B5) / B5) * 100) -> 67.647059 | O5: 12502 | P5: =L5 / O5 * 100000 -> 911.8541
A6: Yorkdale-Glen Park | B6: 67 | C6: 53 | D6: 41 | E6: 52 | F6: 63 | G6: 62 | H6: 88 | I6: 96 | J6: 196 | K6: 202 | L6: 112 | M6: 1032 | N6: =IF(B6=0, "", ((L6 - B6) / B6) * 100) -> 67.164179 | O6: 14695 | P6: =L6 / O6 * 100000 -> 762.164
A7: York University Heights | B7: 109 | C7: 101 | D7: 109 | E7: 93 | F7: 90 | G7: 148 | H7: 187 | I7: 174 | J7: 235 | K7: 264 | L7: 225 | M7: 1735 | N7: =IF(B7=0, "", ((L7 - B7) / B7) * 100) -> 106.42202 | O7: 34002 | P7: =L7 / O7 * 100000 -> 661.72578
A8: Agincourt North | B8: 17 | C8: 29 | D8: 18 | E8: 33 | F8: 42 | G8: 42 | H8: 63 | I8: 52 | J8: 49 | K8: 125 | L8: 128 | M8: 598 | N8: =IF(B8=0, "", ((L8 - B8) / B8) * 100) -> 652.94118 | O8: 20666 | P8: =L8 / O8 * 100000 -> 619.37482
A9: Oakdale-Beverley Heights | B9: 66 | C9: 70 | D9: 51 | E9: 53 | F9: 75 | G9: 92 | H9: 103 | I9: 115 | J9: 106 | K9: 164 | L9: 110 | M9: 1005 | N9: =IF(B9=0, "", ((L9 - B9) / B9) * 100) -> 66.666667 | O9: 18265 | P9: =L9 / O9 * 100000 -> 602.24473
A10: Weston | B10: 55 | C10: 35 | D10: 40 | E10: 44 | F10: 55 | G10: 46 | H10: 78 | I10: 60 | J10: 99 | K10: 108 | L10: 90 | M10: 710 | N10: =IF(B10=0, "", ((L10 - B10) / B10) * 100) -> 63.636364 | O10: 15152 | P10: =L10 / O10 * 100000 -> 593.98099
A11: Bedford Park-Nortown | B11: 40 | C11: 40 | D11: 30 | E11: 47 | F11: 49 | G11: 63 | H11: 81 | I11: 105 | J11: 172 | K11: 228 | L11: 101 | M11: 956 | N11: =IF(B11=0, "", ((L11 - B11) / B11) * 100) -> 152.5 | O11: 17276 | P11: =L11 / O11 * 100000 -> 584.62607
A12: Glenfield-Jane Heights | B12: 44 | C12: 50 | D12: 64 | E12: 50 | F12: 68 | G12: 83 | H12: 120 | I12: 106 | J12: 155 | K12: 120 | L12: 103 | M12: 963 | N12: =IF(B12=0, "", ((L12 - B12) / B12) * 100) -> 134.09091 | O12: 18736 | P12: =L12 / O12 * 100000 -> 549.74381
A13: Islington | B13: 27 | C13: 25 | D13: 33 | E13: 24 | F13: 36 | G13: 57 | H13: 50 | I13: 58 | J13: 96 | K13: 174 | L13: 83 | M13: 663 | N13: =IF(B13=0, "", ((L13 - B13) / B13) * 100) -> 207.40741 | O13: 15556 | P13: =L13 / O13 * 100000 -> 533.55618
... A159: Blake-Jones | B159: 4 | C159: 3 | D159: 5 | E159: 6 | F159: 10 | G159: 8 | H159: 7 | I159: 5 | J159: 9 | K159: 6 | L159: 5 | M159: 68 | N159: =IF(B159=0, "", ((L159 - B159) / B159) * 100) -> 25 | O159: 21692 | P159: =L159 / O159 * 100000 -> 23.049972
